Workbook
Name AssetP: 'Depreciation Calculator'!$D$8
Name AssetPrice: 'Depreciation Calculator'!$D$8

Sheet Depreciation Calculator
C2: Coachx.live
C3: Asset Depreciation Analysis & Calculator | G3: Straight line method | K3: Year | L3: Depreciation in SLM
G4: Depreciation Schedule | K4: 1 | L4: 45000
B5: Straight Line Method | G5: Year | H5: Year on Year Depreciation Amount | I5: Book Value | K5: 2 | L5: 45000
B6: Asset Cost | D6: 450000 | G6: 1 | H6: 45000 | I6: 455000 | K6: 3 | L6: 45000
B7: Additonal Asset Cost | D7: 50000 | G7: 2 | H7: 45000 | I7: 410000 | K7: 4 | L7: 45000
B8: Asset Price | D8: =SUM(D6,D7) -> 500000 | G8: 3 | H8: 45000 | I8: 365000 | K8: 5 | L8: 45000
B9: Scrap Value | D9: 50000 | G9: 4 | H9: 45000 | I9: 320000 | K9: 6 | L9: 45000
B10: Estimated Life Span (Years) | D10: 10 | G10: 5 | H10: 45000 | I10: 275000 | K10: 7 | L10: 45000
B11: Depreciation / Year as per Straight Line Method | D11: =IF(D8="", "", SLN($D$8,$D$9,$D$10)) -> 45000 | G11: 6 | H11: 45000 | I11: 230000 | K11: 8 | L11: 45000
B12: Depreciation Percentage | D12: =IFERROR(D11/D8,"") -> 0.09 | G12: 7 | H12: 45000 | I12: 185000 | K12: 9 | L12: 45000
B13: Total Depreciation For Its Life Span | D13: =IF(D8="", "", D11*D10) -> 450000 | G13: 8 | H13: 45000 | I13: 140000 | K13: 10 | L13: 45000
B14: Depreciated Book Value After Its Life Span | D14: =IF(D8="", "", D8-D13) -> 50000 | G14: 9 | H14: 45000 | I14: 95000
B15: Balance Amount | D15: =IF(D8="", "", D9-D14) -> 0 | G15: 10 | H15: 45000 | I15: 50000
B17: Diminishing Balance Method
B18: Asset Cost | D18: 450000 | G18: Diminishing Balance Method | K18: Year | L18: Depreciation in DBM
B19: Additonal Asset Cost | D19: 50000 | G19: Depreciation Schedule | K19: 1 | L19: 102835.88
B20: Asset Price | D20: =SUM(D18,D19) -> 500000 | G20: Year | H20: Year on Year Depreciation Amount | I20: Book Value | K20: 2 | L20: 81685.445
B21: Scrap Value | D21: 50000 | G21: 1 | H21: 102835.88 | I21: 397164.12 | K21: 3 | L21: 64885.055
B22: Estimated Life Span (Years) | D22: 10 | G22: 2 | H22: 81685.445 | I22: 315478.67 | K22: 4 | L22: 51540.032
B23: Rate of Depreciation as per Diminishing Balance Method | D23: =IF(D20="","",1-(D21/D20)^(1/D22)) -> 0.20567177 | G23: 3 | H23: 64885.055 | I23: 250593.62 | K23: 5 | L23: 40939.702
B24: Depreciation Schedule | G24: 4 | H24: 51540.032 | I24: 199053.59 | K24: 6 | L24: 32519.561
B25: Year | C25: Year on Year Depreciation Amount | D25: Book Value | G25: 5 | H25: 40939.702 | I25: 158113.88 | K25: 7 | L25: 25831.206
B26: 1 | C26: =IFERROR(IF(D20>$D$21, D20*$D$23, ""), "") -> 102835.88 | D26: =D20-C26 -> 397164.12 | G26: 6 | H26: 32519.561 | I26: 125594.32 | K26: 8 | L26: 20518.456
B27: 2 | C27: =IFERROR(IF(D26>$D$21, D26*$D$23, ""), "") -> 81685.445 | D27: =IFERROR(D26-C27, "") -> 315478.67 | G27: 7 | H27: 25831.206 | I27: 99763.116 | K27: 9 | L27: 16298.389
B28: 3 | C28: =IFERROR(IF(D27>$D$21, (D27*$D$23), ""),"") -> 64885.055 | D28: =IFERROR(D27-C28, "") -> 250593.62 | G28: 8 | H28: 20518.456 | I28: 79244.66 | K28: 10 | L28: 12946.271
B29: 4 | C29: =IFERROR(IF(D28>$D$21, (D28*$D$23), ""),"") -> 51540.032 | D29: =IFERROR(D28-C29, "") -> 199053.59 | G29: 9 | H29: 16298.389 | I29: 62946.271
B30: 5 | C30: =IFERROR(IF(D29>$D$21, (D29*$D$23), ""),"") -> 40939.702 | D30: =IFERROR(D29-C30, "") -> 158113.88 | G30: 10 | H30: 12946.271 | I30: 50000
B31: 6 | C31: =IFERROR(IF(D30>$D$21, (D30*$D$23), ""),"") -> 32519.561 | D31: =IFERROR(D30-C31, "") -> 125594.32
B32: 7 | C32: =IFERROR(IF(D31>$D$21, (D31*$D$23), ""),"") -> 25831.206 | D32: =IFERROR(D31-C32, "") -> 99763.116
B33: 8 | C33: =IFERROR(IF(D32>$D$21, D32*$D$23, ""), "") -> 20518.456 | D33: =IFERROR(D32 - C33, "") -> 79244.66
B34: 9 | C34: =IFERROR(IF(D33>$D$21, (D33*$D$23), ""),"") -> 16298.389 | D34: =D33 - C34 -> 62946.271 | G34: Year | H34: Depreciation in SLM | I34: Depreciation in DBM
B35: 10 | C35: =IFERROR(IF(D34>$D$21, (D34*$D$23), ""),"") -> 12946.271 | D35: =IFERROR(D34-C35, "") -> 50000 | G35: 1 | H35: 45000 | I35: 102835.88
C36: =IFERROR(IF(D36>$D$21, (D36*$D$23), ""),"") | G36: 2 | H36: 45000 | I36: 81685.445
C37: =IFERROR(IF(D37>$D$21, (D37*$D$23), ""),"") | D37: =IFERROR(D36-C36, "") | G37: 3 | H37: 45000 | I37: 64885.055
C38: =IFERROR(IF(D38>$D$21, (D38*$D$23), ""),"") | D38: =IFERROR(D37-C37, "") | G38: 4 | H38: 45000 | I38: 51540.032
C39: =IFERROR(IF(D39>$D$21, (D39*$D$23), ""),"") | D39: =IFERROR(D38-C38, "") | G39: 5 | H39: 45000 | I39: 40939.702
C40: =IFERROR(IF(D40>$D$21, (D40*$D$23), ""),"") | D40: =IFERROR(D39-C39, "") | G40: 6 | H40: 45000 | I40: 32519.561
C41: =IFERROR(IF(D41>$D$21, (D41*$D$23), ""),"") | D41: =IFERROR(D40-C40, "") | G41: 7 | H41: 45000 | I41: 25831.206
C42: =IFERROR(IF(D42>$D$21, (D42*$D$23), ""),"") | D42: =IFERROR(D41-C41, "") | G42: 8 | H42: 45000 | I42: 20518.456
...

Sheet Analysis
A1: Analysis Questions | B1: Value | C1: Formula
A2: Annual Depreciation (SLM) | B2: =('Depreciation Calculator'!D6+'Depreciation Calculator'!D7-'Depreciation Calculator'!D9)/'Depreciation Calculator'!D10 -> 45000 | C2: (Asset Cost + Additional Costs − Scrap Value) / Lifespan
A3: Total Depreciation(SLM) | B3: =('Depreciation Calculator'!D6+'Depreciation Calculator'!D7-'Depreciation Calculator'!D9) -> 450000 | C3: (Asset Cost + Additional Costs − Scrap Value)
A4: Depreciated Book Value after life span | B4: ='Depreciation Calculator'!D14 -> 50000
A5: Rate of Depreciation(DBM) | B5: ='Depreciation Calculator'!D23 -> 0.20567177 | C5: Depreciation rate percentage
A6: Year 2's Depreciation amount | B6: ='Depreciation Calculator'!D26*'Depreciation Calculator'!D23 -> 81685.445 | C6: Book Value at start of Year2 * Rate of Depreciation
A7: Year 4's book value | B7: ='Depreciation Calculator'!D28-'Depreciation Calculator'!C29 -> 199053.59 | C7: Book Value of Year3 - Year on Year Depreciation amount
A8: Total depreciation (DBM) | B8: =SUM('Depreciation Calculator'!C26:C35) -> 450000 | C8: sum of year on year depreciation
A9: Book Value after lifespan | B9: ='Depreciation Calculator'!D21 -> 50000 | C9: Scrap Value
A10: Diminishing balance method has slightly higher depreciation value than SLM, It varies by almost $999.

Sheet Dashboard
F1: DEPRECIATION ANALYSIS DASHBOARD
